Sourcing python-remove-tests-dir-hook
Sourcing python-catch-conflicts-hook.sh
Sourcing python-remove-bin-bytecode-hook.sh
Sourcing pip-build-hook
Using pipBuildPhase
Using pipShellHook
Sourcing pip-install-hook
Using pipInstallPhase
Sourcing python-imports-check-hook.sh
Using pythonImportsCheckPhase
Sourcing python-namespaces-hook
@nix { "action": "setPhase", "phase": "unpackPhase" }
unpacking sources
unpacking source archive /nix/store/xrvzynjiyqp75jyyqiz52r1n9vl96sjl-flake8-mutable-1.2.0.tar.gz
source root is flake8-mutable-1.2.0
setting SOURCE_DATE_EPOCH to timestamp 1493002376 of file flake8-mutable-1.2.0/setup.cfg
@nix { "action": "setPhase", "phase": "patchPhase" }
patching sources
@nix { "action": "setPhase", "phase": "configurePhase" }
configuring
no configure script, doing nothing
@nix { "action": "setPhase", "phase": "buildPhase" }
building
Executing pipBuildPhase
Creating a wheel...
[33mWARNING: The directory '/homeless-shelter/.cache/pip' or its parent directory is not owned or is not writable by the current user. The cache has been disabled. Check the permissions and owner of that directory. If executing pip with sudo, you should use sudo's -H flag.[0m[33m
[0mProcessing /build/flake8-mutable-1.2.0
  Running command python setup.py egg_info
  /nix/store/yxl1d0sa5a8a4gz6qn4529w5ijxvh7fd-python3.9-setuptools-61.2.0/lib/python3.9/site-packages/setuptools/installer.py:27: SetuptoolsDeprecationWarning: setuptools.installer is deprecated. Requirements should be satisfied by a PEP 517 installer.
    warnings.warn(
  WARNING: The directory '/homeless-shelter/.cache/pip' or its parent directory is not owned or is not writable by the current user. The cache has been disabled. Check the permissions and owner of that directory. If executing pip with sudo, you should use sudo's -H flag.
  WARNING: Retrying (Retry(total=4, connect=None, read=None, redirect=None, status=None)) after connection broken by 'NewConnectionError('<pip._vendor.urllib3.connection.HTTPSConnection object at 0x7ffff57888e0>: Failed to establish a new connection: [Errno -3] Temporary failure in name resolution')': /simple/pytest-runner/
  WARNING: Retrying (Retry(total=3, connect=None, read=None, redirect=None, status=None)) after connection broken by 'NewConnectionError('<pip._vendor.urllib3.connection.HTTPSConnection object at 0x7ffff5788be0>: Failed to establish a new connection: [Errno -3] Temporary failure in name resolution')': /simple/pytest-runner/
  WARNING: Retrying (Retry(total=2, connect=None, read=None, redirect=None, status=None)) after connection broken by 'NewConnectionError('<pip._vendor.urllib3.connection.HTTPSConnection object at 0x7ffff5788d90>: Failed to establish a new connection: [Errno -3] Temporary failure in name resolution')': /simple/pytest-runner/
  WARNING: Retrying (Retry(total=1, connect=None, read=None, redirect=None, status=None)) after connection broken by 'NewConnectionError('<pip._vendor.urllib3.connection.HTTPSConnection object at 0x7ffff5788f40>: Failed to establish a new connection: [Errno -3] Temporary failure in name resolution')': /simple/pytest-runner/
  WARNING: Retrying (Retry(total=0, connect=None, read=None, redirect=None, status=None)) after connection broken by 'NewConnectionError('<pip._vendor.urllib3.connection.HTTPSConnection object at 0x7ffff57a9130>: Failed to establish a new connection: [Errno -3] Temporary failure in name resolution')': /simple/pytest-runner/
  ERROR: Could not find a version that satisfies the requirement pytest-runner (from versions: none)
  ERROR: No matching distribution found for pytest-runner
  Traceback (most recent call last):
    File "/nix/store/yxl1d0sa5a8a4gz6qn4529w5ijxvh7fd-python3.9-setuptools-61.2.0/lib/python3.9/site-packages/setuptools/installer.py", line 82, in fetch_build_egg
      subprocess.check_call(cmd)
    File "/nix/store/wnrc4daqbd6v5ifqlxsj75ky8556zy0p-python3-3.9.12/lib/python3.9/subprocess.py", line 373, in check_call
      raise CalledProcessError(retcode, cmd)
  subprocess.CalledProcessError: Command '['/nix/store/wnrc4daqbd6v5ifqlxsj75ky8556zy0p-python3-3.9.12/bin/python3.9', '-m', 'pip', '--disable-pip-version-check', 'wheel', '--no-deps', '-w', '/build/tmp7_kngwtd', '--quiet', 'pytest-runner']' returned non-zero exit status 1.

  The above exception was the direct cause of the following exception:

  Traceback (most recent call last):
    File "<string>", line 2, in <module>
    File "<pip-setuptools-caller>", line 34, in <module>
    File "/build/flake8-mutable-1.2.0/setup.py", line 5, in <module>
      setuptools.setup(
    File "/nix/store/yxl1d0sa5a8a4gz6qn4529w5ijxvh7fd-python3.9-setuptools-61.2.0/lib/python3.9/site-packages/setuptools/__init__.py", line 86, in setup
      _install_setup_requires(attrs)
    File "/nix/store/yxl1d0sa5a8a4gz6qn4529w5ijxvh7fd-python3.9-setuptools-61.2.0/lib/python3.9/site-packages/setuptools/__init__.py", line 80, in _install_setup_requires
      dist.fetch_build_eggs(dist.setup_requires)
    File "/nix/store/yxl1d0sa5a8a4gz6qn4529w5ijxvh7fd-python3.9-setuptools-61.2.0/lib/python3.9/site-packages/setuptools/dist.py", line 861, in fetch_build_eggs
      resolved_dists = pkg_resources.working_set.resolve(
    File "/nix/store/yxl1d0sa5a8a4gz6qn4529w5ijxvh7fd-python3.9-setuptools-61.2.0/lib/python3.9/site-packages/pkg_resources/__init__.py", line 777, in resolve
      dist = best[req.key] = env.best_match(
    File "/nix/store/yxl1d0sa5a8a4gz6qn4529w5ijxvh7fd-python3.9-setuptools-61.2.0/lib/python3.9/site-packages/pkg_resources/__init__.py", line 1062, in best_match
      return self.obtain(req, installer)
    File "/nix/store/yxl1d0sa5a8a4gz6qn4529w5ijxvh7fd-python3.9-setuptools-61.2.0/lib/python3.9/site-packages/pkg_resources/__init__.py", line 1074, in obtain
      return installer(requirement)
    File "/nix/store/yxl1d0sa5a8a4gz6qn4529w5ijxvh7fd-python3.9-setuptools-61.2.0/lib/python3.9/site-packages/setuptools/dist.py", line 941, in fetch_build_egg
      return fetch_build_egg(self, req)
    File "/nix/store/yxl1d0sa5a8a4gz6qn4529w5ijxvh7fd-python3.9-setuptools-61.2.0/lib/python3.9/site-packages/setuptools/installer.py", line 84, in fetch_build_egg
      raise DistutilsError(str(e)) from e
  distutils.errors.DistutilsError: Command '['/nix/store/wnrc4daqbd6v5ifqlxsj75ky8556zy0p-python3-3.9.12/bin/python3.9', '-m', 'pip', '--disable-pip-version-check', 'wheel', '--no-deps', '-w', '/build/tmp7_kngwtd', '--quiet', 'pytest-runner']' returned non-zero exit status 1.
  [1;31merror[0m: [1msubprocess-exited-with-error[0m
  
  [31mÃ—[0m [32mpython setup.py egg_info[0m did not run successfully.
  [31mâ”‚[0m exit code: [1;36m1[0m
  [31mâ•°â”€>[0m See above for output.
  
  [1;35mnote[0m: This error originates from a subprocess, and is likely not a problem with pip.
  [1;35mfull command[0m: [34m/nix/store/wnrc4daqbd6v5ifqlxsj75ky8556zy0p-python3-3.9.12/bin/python3.9 -c '[0m
[34m  exec(compile('"'"''"'"''"'"'[0m
[34m  # This is <pip-setuptools-caller> -- a caller that pip uses to run setup.py[0m
[34m  #[0m
[34m  # - It imports setuptools before invoking setup.py, to enable projects that directly[0m
[34m  #   import from `distutils.core` to work with newer packaging standards.[0m
[34m  # - It provides a clear error message when setuptools is not installed.[0m
[34m  # - It sets `sys.argv[0]` to the underlying `setup.py`, when invoking `setup.py` so[0m
[34m  #   setuptools doesn'"'"'t think the script is `-c`. This avoids the following warning:[0m
[34m  #     manifest_maker: standard file '"'"'-c'"'"' not found".[0m
[34m  # - It generates a shim setup.py, for handling setup.cfg-only projects.[0m
[34m  import os, sys, tokenize[0m
[34m  [0m
[34m  try:[0m
[34m      import setuptools[0m
[34m  except ImportError as error:[0m
[34m      print([0m
[34m          "ERROR: Can not execute `setup.py` since setuptools is not available in "[0m
[34m          "the build environment.",[0m
[34m          file=sys.stderr,[0m
[34m      )[0m
[34m      sys.exit(1)[0m
[34m  [0m
[34m  __file__ = %r[0m
[34m  sys.argv[0] = __file__[0m
[34m  [0m
[34m  if os.path.exists(__file__):[0m
[34m      filename = __file__[0m
[34m      with tokenize.open(__file__) as f:[0m
[34m          setup_py_code = f.read()[0m
[34m  else:[0m
[34m      filename = "<auto-generated setuptools caller>"[0m
[34m      setup_py_code = "from setuptools import setup; setup()"[0m
[34m  [0m
[34m  exec(compile(setup_py_code, filename, "exec"))[0m
[34m  '"'"''"'"''"'"' % ('"'"'/build/flake8-mutable-1.2.0/setup.py'"'"',), "<pip-setuptools-caller>", "exec"))' egg_info --egg-base /build/pip-pip-egg-info-r0rodt6k[0m
  [1;35mcwd[0m: /build/flake8-mutable-1.2.0/
  Preparing metadata (setup.py) ... [?25l[?25herror
[1;31merror[0m: [1mmetadata-generation-failed[0m

[31mÃ—[0m Encountered error while generating package metadata.
[31mâ•°â”€>[0m See above for output.

[1;35mnote[0m: This is an issue with the package mentioned above, not pip.
[1;36mhint[0m: See above for details.
